#VRML_SIM R2023b utf8

EXTERNPROTO "https://raw.githubusercontent.com/cyberbotics/webots/R2023b/projects/appearances/protos/BrushedSteel.proto"
EXTERNPROTO "https://raw.githubusercontent.com/cyberbotics/webots/R2023b/projects/appearances/protos/Copper.proto"
EXTERNPROTO "https://raw.githubusercontent.com/cyberbotics/webots/R2023b/projects/appearances/protos/DamascusSteel.proto"
EXTERNPROTO "https://raw.githubusercontent.com/cyberbotics/webots/R2023b/projects/appearances/protos/HammeredCopper.proto"
EXTERNPROTO "https://raw.githubusercontent.com/cyberbotics/webots/R2023b/projects/appearances/protos/SandyGround.proto"
EXTERNPROTO "https://raw.githubusercontent.com/cyberbotics/webots/R2023b/projects/appearances/protos/SolarCell.proto"
EXTERNPROTO "https://raw.githubusercontent.com/cyberbotics/webots/R2023b/projects/objects/backgrounds/protos/TexturedBackground.proto"
EXTERNPROTO "https://raw.githubusercontent.com/cyberbotics/webots/R2023b/projects/objects/backgrounds/protos/TexturedBackgroundLight.proto"
EXTERNPROTO "https://raw.githubusercontent.com/cyberbotics/webots/R2023b/projects/objects/floors/protos/UnevenTerrain.proto"
EXTERNPROTO "https://raw.githubusercontent.com/cyberbotics/webots/R2023b/projects/objects/trees/protos/Forest.proto"

WorldInfo {
}
Viewpoint {
  orientation -0.10815661866136028 -0.001706089996844095 0.9941324032022415 2.908260803256645
  position 0.9674129967728406 -4.946186267349443 5.298458160328519
}
TexturedBackground {
  texture "mars"
}
TexturedBackgroundLight {
  luminosity 2
}
UnevenTerrain {
  appearance SandyGround {
    colorOverride 0.55 0.55 0.4
    textureTransform TextureTransform {
      scale 50 50
    }
  }
}
Forest {
}
Robot {
  translation -6.154269163878886 -3.108244292161464 3.0892285198241836
  rotation 0.09922782339873479 0.06222667118747277 -0.9931171534398525 0.5287982649855262
  children [
    DEF body Shape {
      appearance HammeredCopper {
      }
      geometry Box {
        size 0.7 0.5 0.2
      }
    }
    Solid {
      translation 0 0 0.19
      children [
        DEF panel Shape {
          appearance SolarCell {
          }
          geometry Box {
            size 0.8 0.5 0.01
          }
        }
        Solid {
          translation 0.3 -0.19 -0.05
          children [
            Shape {
              appearance Copper {
              }
              geometry Cylinder {
                height 0.1
                radius 0.02
              }
            }
          ]
          name "solar_panel_support1"
        }
        Solid {
          translation 0.3 0.19 -0.05
          children [
            Shape {
              appearance Copper {
              }
              geometry Cylinder {
                height 0.1
                radius 0.02
              }
            }
          ]
          name "solar_panel_support2"
        }
        Solid {
          translation -0.3 0.19 -0.05
          children [
            Shape {
              appearance Copper {
              }
              geometry Cylinder {
                height 0.1
                radius 0.02
              }
            }
          ]
          name "solar_panel_support3"
        }
        Solid {
          translation -0.3 -0.19 -0.05
          children [
            Shape {
              appearance Copper {
              }
              geometry Cylinder {
                height 0.1
                radius 0.02
              }
            }
          ]
          name "solar_panel_support4"
        }
      ]
      name "solar_panel"
    }
    Solid {
      translation -0.18 -0.24 0
      children [
        Solid {
          translation -0.00017766252744422228 -0.017340268664742475 0.05993637531167906
          rotation -0.9999999929357695 8.124469320562993e-05 -8.676267159571073e-05 1.5708626067521982
          children [
            DEF cylinder1 Shape {
              appearance DamascusSteel {
              }
              geometry Cylinder {
                height 0.09
                radius 0.02
              }
            }
            Solid {
              translation 0 0 -0.05
              children [
                DEF sphere1 Shape {
                  appearance BrushedSteel {
                  }
                  geometry Sphere {
                    radius 0.02
                  }
                }
                Solid {
                  translation 0 0.1 1.79608e-07
                  rotation -1 0 0 -1.5707953071795862
                  children [
                    DEF cylinder2 Shape {
                      appearance BrushedSteel {
                      }
                      geometry Cylinder {
                        height 0.2
                        radius 0.02
                      }
                    }
                    Solid {
                      translation 0 0 -0.11
                      children [
                        DEF sphere1 Shape {
                          appearance BrushedSteel {
                          }
                          geometry Sphere {
                            radius 0.02
                          }
                        }
                        Solid {
                          translation 0 -0.03 -9.99999e-08
                          rotation 1 0 0 1.5708
                          children [
                            DEF cylinder3 Shape {
                              appearance BrushedSteel {
                              }
                              geometry Cylinder {
                                height 0.06
                                radius 0.02
                              }
                            }
                            HingeJoint {
                              jointParameters HingeJointParameters {
                                position 128.50053321760348
                                axis 0 0 1
                                anchor -9.51224e-05 0.00113507 0.0800056
                              }
                              device [
                                RotationalMotor {
                                  name "wheel1_left"
                                }
                              ]
                              endPoint Solid {
                                translation -0.0005953219530357427 0.0026943719463136846 0.07995424362107062
                                rotation -4.33050084571276e-06 1.4616230568273095e-06 -0.9999999999895552 3.4344788829863933
                                children [
                                  DEF wheel Shape {
                                    appearance DamascusSteel {
                                    }
                                    geometry Cylinder {
                                      height 0.15
                                      radius 0.15
                                    }
                                  }
                                ]
                                boundingObject USE wheel
                                physics Physics {
                                  mass 1
                                }
                                linearVelocity 6.95883295502142e-06 -1.926103842725188e-05 -2.952059092536743e-07
                                angularVelocity 9.101195556246965e-08 9.387774878770275e-07 -2.0181082523096956e-06
                              }
                            }
                          ]
                          boundingObject USE cylinder3
                          physics DEF phy1 Physics {
                            mass 1
                          }
                        }
                      ]
                      name "solid(1)"
                      boundingObject USE sphere1
                      physics USE phy1
                    }
                  ]
                  boundingObject USE cylinder2
                  physics USE phy1
                }
              ]
              boundingObject USE sphere1
              physics USE phy1
            }
          ]
          boundingObject USE cylinder1
          physics USE phy1
        }
      ]
      name "wheel1_left_system"
      physics DEF phy1 Physics {
        mass 1
      }
    }
    Solid {
      translation 0.18 -0.24 0
      children [
        Solid {
          translation -0.0001757815149209252 -0.017333744024692788 0.0600545153188472
          rotation -0.9999999930027248 7.374603208071159e-05 -9.249904417794078e-05 1.5708786387286822
          children [
            DEF cylinder1 Shape {
              appearance DamascusSteel {
              }
              geometry Cylinder {
                height 0.09
                radius 0.02
              }
            }
            Solid {
              translation 0 0 -0.05
              children [
                DEF sphere1 Shape {
                  appearance BrushedSteel {
                  }
                  geometry Sphere {
                    radius 0.02
                  }
                }
                Solid {
                  translation 0 0.1 1.79608e-07
                  rotation -1 0 0 -1.5707953071795862
                  children [
                    DEF cylinder2 Shape {
                      appearance BrushedSteel {
                      }
                      geometry Cylinder {
                        height 0.2
                        radius 0.02
                      }
                    }
                    Solid {
                      translation 0 0 -0.11
                      children [
                        DEF sphere1 Shape {
                          appearance BrushedSteel {
                          }
                          geometry Sphere {
                            radius 0.02
                          }
                        }
                        Solid {
                          translation 0 -0.03 -9.99999e-08
                          rotation 1 0 0 1.5708
                          children [
                            DEF cylinder3 Shape {
                              appearance BrushedSteel {
                              }
                              geometry Cylinder {
                                height 0.06
                                radius 0.02
                              }
                            }
                            HingeJoint {
                              jointParameters HingeJointParameters {
                                position -183.2942104711607
                                axis 0 0 1
                                anchor 0.000341778 0.000558794 0.0800055
                              }
                              device [
                                RotationalMotor {
                                  name "wheel2_left"
                                }
                              ]
                              endPoint Solid {
                                translation -0.0005529662315371952 0.0007017676220493544 0.07995173580166282
                                rotation 2.5024548406501925e-06 -3.3748692568155055e-06 0.9999999999911741 5.212103116782959
                                children [
                                  DEF wheel Shape {
                                    appearance DamascusSteel {
                                    }
                                    geometry Cylinder {
                                      height 0.15
                                      radius 0.15
                                    }
                                  }
                                ]
                                boundingObject USE wheel
                                physics Physics {
                                  mass 1
                                }
                                linearVelocity 6.754954080854253e-06 -1.9776611014824198e-05 -6.28125958940014e-07
                                angularVelocity 6.360105294482255e-08 8.29581943816617e-07 -2.0229928072281104e-06
                              }
                            }
                          ]
                          boundingObject USE cylinder3
                          physics DEF phy1 Physics {
                            mass 1
                          }
                        }
                      ]
                      name "solid(1)"
                      boundingObject USE sphere1
                      physics USE phy1
                    }
                  ]
                  boundingObject USE cylinder2
                  physics USE phy1
                }
              ]
              boundingObject USE sphere1
              physics USE phy1
            }
          ]
          boundingObject USE cylinder1
          physics USE phy1
        }
      ]
      name "wheel2_left_system"
      physics USE phy1
    }
    Solid {
      translation -0.18 0.24 0
      children [
        Solid {
          translation -0.000177663 0.0173403 0.0599364
          rotation -0.9999999929357695 8.124469320562993e-05 -8.676267159571073e-05 1.5708626067521982
          children [
            DEF cylinder1 Shape {
              appearance DamascusSteel {
              }
              geometry Cylinder {
                height 0.09
                radius 0.02
              }
            }
            Solid {
              translation 0 0 0.05
              children [
                DEF sphere1 Shape {
                  appearance BrushedSteel {
                  }
                  geometry Sphere {
                    radius 0.02
                  }
                }
                Solid {
                  translation 0 0.1 1.79608e-07
                  rotation -1 0 0 -1.5707953071795862
                  children [
                    DEF cylinder2 Shape {
                      appearance BrushedSteel {
                      }
                      geometry Cylinder {
                        height 0.2
                        radius 0.02
                      }
                    }
                    Solid {
                      translation 0 0 -0.11
                      children [
                        DEF sphere1 Shape {
                          appearance BrushedSteel {
                          }
                          geometry Sphere {
                            radius 0.02
                          }
                        }
                        Solid {
                          translation 0 0.03 -9.99999e-08
                          rotation 1 0 0 1.5708
                          children [
                            DEF cylinder3 Shape {
                              appearance BrushedSteel {
                              }
                              geometry Cylinder {
                                height 0.06
                                radius 0.02
                              }
                            }
                            HingeJoint {
                              jointParameters HingeJointParameters {
                                position 214.90362067820686
                                axis 0 0 1
                                anchor 0.00237208 0.000614304 -0.0799754
                              }
                              device [
                                RotationalMotor {
                                  name "wheel1_right"
                                }
                              ]
                              endPoint Solid {
                                translation 0.0025951711587956735 -0.0009396372445456484 -0.07997536572404963
                                rotation 0.9863710049994583 -0.1645364412196068 2.673179830229245e-06 3.141604652280394
                                children [
                                  DEF wheel Shape {
                                    appearance DamascusSteel {
                                    }
                                    geometry Cylinder {
                                      height 0.15
                                      radius 0.15
                                    }
                                  }
                                ]
                                boundingObject USE wheel
                                physics Physics {
                                  mass 1
                                }
                                linearVelocity 8.084083112226637e-06 -1.9901341632722953e-05 -7.552436750869707e-07
                                angularVelocity 1.239820923847107e-07 9.959272039683566e-07 -2.0154021694174622e-06
                              }
                            }
                          ]
                          boundingObject USE cylinder3
                          physics DEF phy1 Physics {
                            mass 1
                          }
                        }
                      ]
                      name "solid(1)"
                      boundingObject USE sphere1
                      physics USE phy1
                    }
                  ]
                  boundingObject USE cylinder2
                  physics USE phy1
                }
              ]
              boundingObject USE sphere1
              physics USE phy1
            }
          ]
          boundingObject USE cylinder1
          physics USE phy1
        }
      ]
      name "wheel1_right_system"
      physics DEF phy1 Physics {
        mass 1
      }
    }
    Solid {
      translation 0.18 0.24 0
      children [
        Solid {
          translation -0.000177663 0.0173403 0.0599364
          rotation -0.9999999929357695 8.124469320562993e-05 -8.676267159571073e-05 1.5708626067521982
          children [
            DEF cylinder1 Shape {
              appearance DamascusSteel {
              }
              geometry Cylinder {
                height 0.09
                radius 0.02
              }
            }
            Solid {
              translation 0 0 0.05
              children [
                DEF sphere1 Shape {
                  appearance BrushedSteel {
                  }
                  geometry Sphere {
                    radius 0.02
                  }
                }
                Solid {
                  translation 0 0.1 1.79608e-07
                  rotation -1 0 0 -1.5707953071795862
                  children [
                    DEF cylinder2 Shape {
                      appearance BrushedSteel {
                      }
                      geometry Cylinder {
                        height 0.2
                        radius 0.02
                      }
                    }
                    Solid {
                      translation 0 0 -0.11
                      children [
                        DEF sphere1 Shape {
                          appearance BrushedSteel {
                          }
                          geometry Sphere {
                            radius 0.02
                          }
                        }
                        Solid {
                          translation 0 0.03 -9.99999e-08
                          rotation 1 0 0 1.5708
                          children [
                            DEF cylinder3 Shape {
                              appearance BrushedSteel {
                              }
                              geometry Cylinder {
                                height 0.06
                                radius 0.02
                              }
                            }
                            HingeJoint {
                              jointParameters HingeJointParameters {
                                position 209.363506998146
                                axis 0 0 1
                                anchor 0.00237208 0.000614304 -0.0799754
                              }
                              device [
                                RotationalMotor {
                                  name "wheel2_right"
                                }
                              ]
                              endPoint Solid {
                                translation 0.0035876866254184376 -0.00037907588145103346 -0.07997536572404963
                                rotation -0.9788062144346013 -0.20478865833856097 -3.127474733245962e-07 3.141579532580158
                                children [
                                  DEF wheel Shape {
                                    appearance DamascusSteel {
                                    }
                                    geometry Cylinder {
                                      height 0.15
                                      radius 0.15
                                    }
                                  }
                                ]
                                boundingObject USE wheel
                                physics Physics {
                                  mass 1
                                }
                                linearVelocity 8.803311197024045e-06 -2.097614255414371e-05 -8.927982392492539e-07
                                angularVelocity 5.311298659830202e-06 9.860012111918252e-06 -1.5895770058369155e-06
                              }
                            }
                          ]
                          boundingObject USE cylinder3
                          physics DEF phy1 Physics {
                            mass 1
                          }
                        }
                      ]
                      name "solid(1)"
                      boundingObject USE sphere1
                      physics USE phy1
                    }
                  ]
                  boundingObject USE cylinder2
                  physics USE phy1
                }
              ]
              boundingObject USE sphere1
              physics USE phy1
            }
          ]
          boundingObject USE cylinder1
          physics USE phy1
        }
      ]
      name "wheel2_right_system"
      physics DEF phy1 Physics {
        mass 1
      }
    }
  ]
  boundingObject USE body
  physics DEF phy Physics {
    mass 1
  }
  controller "Rover_Controller"
  linearVelocity 7.744676146106998e-06 -1.9992825266825056e-05 -1.400008181844896e-06
  angularVelocity 9.589685746791517e-08 9.22275952082293e-07 -2.0277124048194465e-06
}
